Traceback (most recent call last):
  File "C:\Apps\Anaconda\envs\fyp\lib\site-packages\pandas\core\indexes\base.py", line 3621, in get_loc
    return self._engine.get_loc(casted_key)
  File "pandas\_libs\index.pyx", line 136, in pandas._libs.index.IndexEngine.get_loc
  File "pandas\_libs\index.pyx", line 163, in pandas._libs.index.IndexEngine.get_loc
  File "pandas\_libs\hashtable_class_helper.pxi", line 5198, in pandas._libs.hashtable.PyObjectHashTable.get_item
  File "pandas\_libs\hashtable_class_helper.pxi", line 5206, in pandas._libs.hashtable.PyObjectHashTable.get_item
KeyError: 'Weight'
The above exception was the direct cause of the following exception:
Traceback (most recent call last):
  File "c:\Users\yjn_1\Documents\GitHub\Modeling-relationships-between-object-properties\experiment\train_experiment_model.py", line 85, in <module>
    quantize.quantization(df, num_levels, save_path = FATHER, save_file = True, strategy=strategy, figure_on = False)
  File "C:\Users\yjn_1\Documents\GitHub\Modeling-relationships-between-object-properties\dataset\amazon\quantize.py", line 108, in quantization
    hist_df[head] == X_binned
  File "C:\Apps\Anaconda\envs\fyp\lib\site-packages\pandas\core\frame.py", line 3505, in __getitem__
    indexer = self.columns.get_loc(key)
  File "C:\Apps\Anaconda\envs\fyp\lib\site-packages\pandas\core\indexes\base.py", line 3623, in get_loc
    raise KeyError(key) from err
KeyError: 'Weight'